Workbook

Sheet Start Here
A1: LEHS SY 2026-2027 Schedule & School Calendar
A2: Converted from weekschedule.pdf (scanned, 2 pages). Times and dates are real Excel values, so they sort, filter and import.
A4: What's in this workbook
A5: Bell Schedule | B5: One row per block, Monday-Friday. Instruction and lunch minutes in separate columns.
A6: Lunch Waves | B6: Every printed L1-L4 lunch window inside the 90+30 blocks.
A7: Block Summary | B7: How often each block meets and how many minutes a week it gets.
A8: Calendar Events | B8: All 47 colour-coded dates: closures, early releases, in-service days, graduations.
A9: Monthly Counts | B9: School-day count printed in each month heading, plus a running total.
A10: Academic Deadlines | B10: Elementary trimester and secondary quarter dates from the tables on page 2.
A12: At a glance
A13: Blocks per week | B13: =COUNTA('Bell Schedule'!D2:D27) -> 26
A14: Lunch waves | B14: =COUNTA('Lunch Waves'!D2:D21) -> 20
A15: Calendar dates recorded | B15: =COUNTA('Calendar Events'!A2:A48) -> 47
A16: Scheduled school days | B16: =SUM('Monthly Counts'!B2:B11) -> 180
A17: Maximum with 5 snow days | B17: =SUM('Monthly Counts'!B2:B10)+'Monthly Counts'!C11 -> 185
A18: Instructional minutes per lettered block, per week | B18: ='Block Summary'!C2 -> 240
A20: How the source was read
A21: - Source: weekschedule.pdf - page 1 'SY 26-27 LEHS Schedule', page 2 'Lynn Public Schools 2026-2027 School Calendar'. The PDF is a scan with no extractable text, so both pages were transcribed from the image and re-checked against it.
A22: - The 90+30 blocks run longer on the clock than 120 minutes because the four lunch waves have transition gaps between them. Start and End on the Bell Schedule tab cover the whole block-plus-lunch window; the Clock vs Scheduled column shows the gap.
A23: - Wednesday's D block is printed as 60 minutes, but its printed times (1:29-2:30) span 61. Both values are kept exactly as printed rather than reconciled.
A24: - Wednesday's third block is printed only as 'X'. The PDF never says what X block is, so it is left unlabelled here.
A25: - Holiday names are NOT printed on the source calendar. The 'Likely Holiday' column on Calendar Events is inferred from the dates and is marked as such - verify before relying on it.
A26: - Every block A-G gets exactly 240 instructional minutes a week (X gets 45). That total falling out evenly is a good sign the times were transcribed correctly.

Sheet Bell Schedule
A1: Day # | B1: Day | C1: Period | D1: Block | E1: Start | F1: End | G1: Clock Window (min) | H1: Instruction (min) | I1: Lunch (min) | J1: Scheduled Total (min) | K1: Clock vs Scheduled | L1: Printed Label | M1: Notes
A2: 1 | B2: Monday | C2: 1 | D2: A | E2: 0.32291667 | F2: 0.36805556 | G2: =ROUND((F2-E2)*1440,0) -> 65 | H2: 65 | I2: 0 | J2: =H2+I2 -> 65 | K2: =G2-J2 -> 0 | L2: 65
A3: 1 | B3: Monday | C3: 2 | D3: B | E3: 0.37152778 | F3: 0.40972222 | G3: =ROUND((F3-E3)*1440,0) -> 55 | H3: 55 | I3: 0 | J3: =H3+I3 -> 55 | K3: =G3-J3 -> 0 | L3: 55
A4: 1 | B4: Monday | C4: 3 | D4: C | E4: 0.41319444 | F4: 0.45486111 | G4: =ROUND((F4-E4)*1440,0) -> 60 | H4: 60 | I4: 0 | J4: =H4+I4 -> 60 | K4: =G4-J4 -> 0 | L4: 60
A5: 1 | B5: Monday | C5: 4 | D5: D | E5: 0.45833333 | F5: 0.54791667 | G5: =ROUND((F5-E5)*1440,0) -> 129 | H5: 90 | I5: 30 | J5: =H5+I5 -> 120 | K5: =G5-J5 -> 9 | L5: 90+30 | M5: Rotating 30-min lunch; see Lunch Waves
A6: 1 | B6: Monday | C6: 5 | D6: E | E6: 0.55208333 | F6: 0.60416667 | G6: =ROUND((F6-E6)*1440,0) -> 75 | H6: 75 | I6: 0 | J6: =H6+I6 -> 75 | K6: =G6-J6 -> 0 | L6: 75
A7: 2 | B7: Tuesday | C7: 1 | D7: F | E7: 0.32291667 | F7: 0.36805556 | G7: =ROUND((F7-E7)*1440,0) -> 65 | H7: 65 | I7: 0 | J7: =H7+I7 -> 65 | K7: =G7-J7 -> 0 | L7: 65
A8: 2 | B8: Tuesday | C8: 2 | D8: A | E8: 0.37152778 | F8: 0.40972222 | G8: =ROUND((F8-E8)*1440,0) -> 55 | H8: 55 | I8: 0 | J8: =H8+I8 -> 55 | K8: =G8-J8 -> 0 | L8: 55
A9: 2 | B9: Tuesday | C9: 3 | D9: B | E9: 0.41319444 | F9: 0.45833333 | G9: =ROUND((F9-E9)*1440,0) -> 65 | H9: 65 | I9: 0 | J9: =H9+I9 -> 65 | K9: =G9-J9 -> 0 | L9: 65
A10: 2 | B10: Tuesday | C10: 4 | D10: C | E10: 0.46180556 | F10: 0.55138889 | G10: =ROUND((F10-E10)*1440,0) -> 129 | H10: 90 | I10: 30 | J10: =H10+I10 -> 120 | K10: =G10-J10 -> 9 | L10: 90+30 | M10: Rotating 30-min lunch; see Lunch Waves
A11: 2 | B11: Tuesday | C11: 5 | D11: G | E11: 0.55555556 | F11: 0.60416667 | G11: =ROUND((F11-E11)*1440,0) -> 70 | H11: 70 | I11: 0 | J11: =H11+I11 -> 70 | K11: =G11-J11 -> 0 | L11: 70
A12: 3 | B12: Wednesday | C12: 1 | D12: A | E12: 0.32291667 | F12: 0.36805556 | G12: =ROUND((F12-E12)*1440,0) -> 65 | H12: 65 | I12: 0 | J12: =H12+I12 -> 65 | K12: =G12-J12 -> 0 | L12: 65
A13: 3 | B13: Wednesday | C13: 2 | D13: F | E13: 0.37083333 | F13: 0.40208333 | G13: =ROUND((F13-E13)*1440,0) -> 45 | H13: 45 | I13: 0 | J13: =H13+I13 -> 45 | K13: =G13-J13 -> 0 | L13: 45
A14: 3 | B14: Wednesday | C14: 3 | D14: X | E14: 0.40486111 | F14: 0.43611111 | G14: =ROUND((F14-E14)*1440,0) -> 45 | H14: 45 | I14: 0 | J14: =H14+I14 -> 45 | K14: =G14-J14 -> 0 | L14: 45 | M14: Printed only as 'X'; the PDF does not say what X block is
A15: 3 | B15: Wednesday | C15: 4 | D15: G | E15: 0.43888889 | F15: 0.46666667 | G15: =ROUND((F15-E15)*1440,0) -> 40 | H15: 40 | I15: 0 | J15: =H15+I15 -> 40 | K15: =G15-J15 -> 0 | L15: 40
A16: 3 | B16: Wednesday | C16: 5 | D16: E | E16: 0.46944444 | F16: 0.55902778 | G16: =ROUND((F16-E16)*1440,0) -> 129 | H16: 90 | I16: 30 | J16: =H16+I16 -> 120 | K16: =G16-J16 -> 9 | L16: 90+30 | M16: Rotating 30-min lunch; see Lunch Waves
A17: 3 | B17: Wednesday | C17: 6 | D17: D | E17: 0.56180556 | F17: 0.60416667 | G17: =ROUND((F17-E17)*1440,0) -> 61 | H17: 60 | I17: 0 | J17: =H17+I17 -> 60 | K17: =G17-J17 -> 1 | L17: 60 | M17: Printed as 60 min; 1:29-2:30 spans 61 clock minutes
A18: 4 | B18: Thursday | C18: 1 | D18: F | E18: 0.32291667 | F18: 0.36805556 | G18: =ROUND((F18-E18)*1440,0) -> 65 | H18: 65 | I18: 0 | J18: =H18+I18 -> 65 | K18: =G18-J18 -> 0 | L18: 65
A19: 4 | B19: Thursday | C19: 2 | D19: A | E19: 0.37152778 | F19: 0.40972222 | G19: =ROUND((F19-E19)*1440,0) -> 55 | H19: 55 | I19: 0 | J19: =H19+I19 -> 55 | K19: =G19-J19 -> 0 | L19: 55
A20: 4 | B20: Thursday | C20: 3 | D20: B | E20: 0.41319444 | F20: 0.45833333 | G20: =ROUND((F20-E20)*1440,0) -> 65 | H20: 65 | I20: 0 | J20: =H20+I20 -> 65 | K20: =G20-J20 -> 0 | L20: 65
A21: 4 | B21: Thursday | C21: 4 | D21: C | E21: 0.46180556 | F21: 0.55138889 | G21: =ROUND((F21-E21)*1440,0) -> 129 | H21: 90 | I21: 30 | J21: =H21+I21 -> 120 | K21: =G21-J21 -> 9 | L21: 90+30 | M21: Rotating 30-min lunch; see Lunch Waves
A22: 4 | B22: Thursday | C22: 5 | D22: G | E22: 0.55555556 | F22: 0.60416667 | G22: =ROUND((F22-E22)*1440,0) -> 70 | H22: 70 | I22: 0 | J22: =H22+I22 -> 70 | K22: =G22-J22 -> 0 | L22: 70
A23: 5 | B23: Friday | C23: 1 | D23: F | E23: 0.32291667 | F23: 0.36805556 | G23: =ROUND((F23-E23)*1440,0) -> 65 | H23: 65 | I23: 0 | J23: =H23+I23 -> 65 | K23: =G23-J23 -> 0 | L23: 65
A24: 5 | B24: Friday | C24: 2 | D24: B | E24: 0.37152778 | F24: 0.40972222 | G24: =ROUND((F24-E24)*1440,0) -> 55 | H24: 55 | I24: 0 | J24: =H24+I24 -> 55 | K24: =G24-J24 -> 0 | L24: 55
A25: 5 | B25: Friday | C25: 3 | D25: G | E25: 0.41319444 | F25: 0.45486111 | G25: =ROUND((F25-E25)*1440,0) -> 60 | H25: 60 | I25: 0 | J25: =H25+I25 -> 60 | K25: =G25-J25 -> 0 | L25: 60
A26: 5 | B26: Friday | C26: 4 | D26: D | E26: 0.45833333 | F26: 0.54930556 | G26: =ROUND((F26-E26)*1440,0) -> 131 | H26: 90 | I26: 30 | J26: =H26+I26 -> 120 | K26: =G26-J26 -> 11 | L26: 90+30 | M26: Rotating 30-min lunch; see Lunch Waves
A27: 5 | B27: Friday | C27: 5 | D27: E | E27: 0.55208333 | F27: 0.60416667 | G27: =ROUND((F27-E27)*1440,0) -> 75 | H27: 75 | I27: 0 | J27: =H27+I27 -> 75 | K27: =G27-J27 -> 0 | L27: 75
A29: Source: weekschedule.pdf p.1. Minute columns are formulas, not typed numbers.

Sheet Lunch Waves
A1: Day # | B1: Day | C1: Parent Block | D1: Lunch Wave | E1: Start | F1: End | G1: Minutes
A2: 1 | B2: Monday | C2: D | D2: L1 | E2: 0.45833333 | F2: 0.47916667 | G2: =ROUND((F2-E2)*1440,0) -> 30
A3: 1 | B3: Monday | C3: D | D3: L2 | E3: 0.48125 | F3: 0.50208333 | G3: =ROUND((F3-E3)*1440,0) -> 30
A4: 1 | B4: Monday | C4: D | D4: L3 | E4: 0.50416667 | F4: 0.525 | G4: =ROUND((F4-E4)*1440,0) -> 30
A5: 1 | B5: Monday | C5: D | D5: L4 | E5: 0.52708333 | F5: 0.54791667 | G5: =ROUND((F5-E5)*1440,0) -> 30
A6: 2 | B6: Tuesday | C6: C | D6: L1 | E6: 0.46180556 | F6: 0.48263889 | G6: =ROUND((F6-E6)*1440,0) -> 30
A7: 2 | B7: Tuesday | C7: C | D7: L2 | E7: 0.48472222 | F7: 0.50555556 | G7: =ROUND((F7-E7)*1440,0) -> 30
A8: 2 | B8: Tuesday | C8: C | D8: L3 | E8: 0.50763889 | F8: 0.52847222 | G8: =ROUND((F8-E8)*1440,0) -> 30
A9: 2 | B9: Tuesday | C9: C | D9: L4 | E9: 0.53055556 | F9: 0.55138889 | G9: =ROUND((F9-E9)*1440,0) -> 30
A10: 3 | B10: Wednesday | C10: E | D10: L1 | E10: 0.46944444 | F10: 0.49027778 | G10: =ROUND((F10-E10)*1440,0) -> 30
A11: 3 | B11: Wednesday | C11: E | D11: L2 | E11: 0.49236111 | F11: 0.51319444 | G11: =ROUND((F11-E11)*1440,0) -> 30
A12: 3 | B12: Wednesday | C12: E | D12: L3 | E12: 0.51527778 | F12: 0.53611111 | G12: =ROUND((F12-E12)*1440,0) -> 30
A13: 3 | B13: Wednesday | C13: E | D13: L4 | E13: 0.53819444 | F13: 0.55902778 | G13: =ROUND((F13-E13)*1440,0) -> 30
... A21: 5 | B21: Friday | C21: D | D21: L4 | E21: 0.52847222 | F21: 0.54930556 | G21: =ROUND((F21-E21)*1440,0) -> 30
A23: Source: weekschedule.pdf p.1. Each student takes one wave; the block meets around it.

Sheet Block Summary
A1: Block | B1: Meets per Week | C1: Instruction (min/wk) | D1: Lunch (min/wk) | E1: Total Student Time (min/wk) | F1: Mon | G1: Tue | H1: Wed | I1: Thu | J1: Fri
A2: A | B2: =COUNTIF('Bell Schedule'!$D$2:$D$27,$A2) -> 4 | C2: =SUMIF('Bell Schedule'!$D$2:$D$27,$A2,'Bell Schedule'!$H$2:$H$27) -> 240 | D2: =SUMIF('Bell Schedule'!$D$2:$D$27,$A2,'Bell Schedule'!$I$2:$I$27) -> 0 | E2: =C2+D2 -> 240 | F2: =IF(COUNTIFS('Bell Schedule'!$B$2:$B$27,"Monday",'Bell Schedule'!$D$2:$D$27,$A2)=0,"",SUMIFS('Bell Schedule'!$C$2:$C$27,'Bell Schedule'!$B$2:$B$27,"Monday",'Bell Schedule'!$D$2:$D$27,$A2)) -> 1 | G2: =IF(COUNTIFS('Bell Schedule'!$B$2:$B$27,"Tuesday",'Bell Schedule'!$D$2:$D$27,$A2)=0,"",SUMIFS('Bell Schedule'!$C$2:$C$27,'Bell Schedule'!$B$2:$B$27,"Tuesday",'Bell Schedule'!$D$2:$D$27,$A2)) -> 2 | H2: =IF(COUNTIFS('Bell Schedule'!$B$2:$B$27,"Wednesday",'Bell Schedule'!$D$2:$D$27,$A2)=0,"",SUMIFS('Bell Schedule'!$C$2:$C$27,'Bell Schedule'!$B$2:$B$27,"Wednesday",'Bell Schedule'!$D$2:$D$27,$A2)) -> 1 | I2: =IF(COUNTIFS('Bell Schedule'!$B$2:$B$27,"Thursday",'Bell Schedule'!$D$2:$D$27,$A2)=0,"",SUMIFS('Bell Schedule'!$C$2:$C$27,'Bell Schedule'!$B$2:$B$27,"Thursday",'Bell Schedule'!$D$2:$D$27,$A2)) -> 2 | J2: =IF(COUNTIFS('Bell Schedule'!$B$2:$B$27,"Friday",'Bell Schedule'!$D$2:$D$27,$A2)=0,"",SUMIFS('Bell Schedule'!$C$2:$C$27,'Bell Schedule'!$B$2:$B$27,"Friday",'Bell Schedule'!$D$2:$D$27,$A2))
A3: B | B3: =COUNTIF('Bell Schedule'!$D$2:$D$27,$A3) -> 4 | C3: =SUMIF('Bell Schedule'!$D$2:$D$27,$A3,'Bell Schedule'!$H$2:$H$27) -> 240 | D3: =SUMIF('Bell Schedule'!$D$2:$D$27,$A3,'Bell Schedule'!$I$2:$I$27) -> 0 | E3: =C3+D3 -> 240 | F3: =IF(COUNTIFS('Bell Schedule'!$B$2:$B$27,"Monday",'Bell Schedule'!$D$2:$D$27,$A3)=0,"",SUMIFS('Bell Schedule'!$C$2:$C$27,'Bell Schedule'!$B$2:$B$27,"Monday",'Bell Schedule'!$D$2:$D$27,$A3)) -> 2 | G3: =IF(COUNTIFS('Bell Schedule'!$B$2:$B$27,"Tuesday",'Bell Schedule'!$D$2:$D$27,$A3)=0,"",SUMIFS('Bell Schedule'!$C$2:$C$27,'Bell Schedule'!$B$2:$B$27,"Tuesday",'Bell Schedule'!$D$2:$D$27,$A3)) -> 3 | H3: =IF(COUNTIFS('Bell Schedule'!$B$2:$B$27,"Wednesday",'Bell Schedule'!$D$2:$D$27,$A3)=0,"",SUMIFS('Bell Schedule'!$C$2:$C$27,'Bell Schedule'!$B$2:$B$27,"Wednesday",'Bell Schedule'!$D$2:$D$27,$A3)) | I3: =IF(COUNTIFS('Bell Schedule'!$B$2:$B$27,"Thursday",'Bell Schedule'!$D$2:$D$27,$A3)=0,"",SUMIFS('Bell Schedule'!$C$2:$C$27,'Bell Schedule'!$B$2:$B$27,"Thursday",'Bell Schedule'!$D$2:$D$27,$A3)) -> 3 | J3: =IF(COUNTIFS('Bell Schedule'!$B$2:$B$27,"Friday",'Bell Schedule'!$D$2:$D$27,$A3)=0,"",SUMIFS('Bell Schedule'!$C$2:$C$27,'Bell Schedule'!$B$2:$B$27,"Friday",'Bell Schedule'!$D$2:$D$27,$A3)) -> 2
A4: C | B4: =COUNTIF('Bell Schedule'!$D$2:$D$27,$A4) -> 3 | C4: =SUMIF('Bell Schedule'!$D$2:$D$27,$A4,'Bell Schedule'!$H$2:$H$27) -> 240 | D4: =SUMIF('Bell Schedule'!$D$2:$D$27,$A4,'Bell Schedule'!$I$2:$I$27) -> 60 | E4: =C4+D4 -> 300 | F4: =IF(COUNTIFS('Bell Schedule'!$B$2:$B$27,"Monday",'Bell Schedule'!$D$2:$D$27,$A4)=0,"",SUMIFS('Bell Schedule'!$C$2:$C$27,'Bell Schedule'!$B$2:$B$27,"Monday",'Bell Schedule'!$D$2:$D$27,$A4)) -> 3 | G4: =IF(COUNTIFS('Bell Schedule'!$B$2:$B$27,"Tuesday",'Bell Schedule'!$D$2:$D$27,$A4)=0,"",SUMIFS('Bell Schedule'!$C$2:$C$27,'Bell Schedule'!$B$2:$B$27,"Tuesday",'Bell Schedule'!$D$2:$D$27,$A4)) -> 4 | H4: =IF(COUNTIFS('Bell Schedule'!$B$2:$B$27,"Wednesday",'Bell Schedule'!$D$2:$D$27,$A4)=0,"",SUMIFS('Bell Schedule'!$C$2:$C$27,'Bell Schedule'!$B$2:$B$27,"Wednesday",'Bell Schedule'!$D$2:$D$27,$A4)) | I4: =IF(COUNTIFS('Bell Schedule'!$B$2:$B$27,"Thursday",'Bell Schedule'!$D$2:$D$27,$A4)=0,"",SUMIFS('Bell Schedule'!$C$2:$C$27,'Bell Schedule'!$B$2:$B$27,"Thursday",'Bell Schedule'!$D$2:$D$27,$A4)) -> 4 | J4: =IF(COUNTIFS('Bell Schedule'!$B$2:$B$27,"Friday",'Bell Schedule'!$D$2:$D$27,$A4)=0,"",SUMIFS('Bell Schedule'!$C$2:$C$27,'Bell Schedule'!$B$2:$B$27,"Friday",'Bell Schedule'!$D$2:$D$27,$A4))
A5: D | B5: =COUNTIF('Bell Schedule'!$D$2:$D$27,$A5) -> 3 | C5: =SUMIF('Bell Schedule'!$D$2:$D$27,$A5,'Bell Schedule'!$H$2:$H$27) -> 240 | D5: =SUMIF('Bell Schedule'!$D$2:$D$27,$A5,'Bell Schedule'!$I$2:$I$27) -> 60 | E5: =C5+D5 -> 300 | F5: =IF(COUNTIFS('Bell Schedule'!$B$2:$B$27,"Monday",'Bell Schedule'!$D$2:$D$27,$A5)=0,"",SUMIFS('Bell Schedule'!$C$2:$C$27,'Bell Schedule'!$B$2:$B$27,"Monday",'Bell Schedule'!$D$2:$D$27,$A5)) -> 4 | G5: =IF(COUNTIFS('Bell Schedule'!$B$2:$B$27,"Tuesday",'Bell Schedule'!$D$2:$D$27,$A5)=0,"",SUMIFS('Bell Schedule'!$C$2:$C$27,'Bell Schedule'!$B$2:$B$27,"Tuesday",'Bell Schedule'!$D$2:$D$27,$A5)) | H5: =IF(COUNTIFS('Bell Schedule'!$B$2:$B$27,"Wednesday",'Bell Schedule'!$D$2:$D$27,$A5)=0,"",SUMIFS('Bell Schedule'!$C$2:$C$27,'Bell Schedule'!$B$2:$B$27,"Wednesday",'Bell Schedule'!$D$2:$D$27,$A5)) -> 6 | I5: =IF(COUNTIFS('Bell Schedule'!$B$2:$B$27,"Thursday",'Bell Schedule'!$D$2:$D$27,$A5)=0,"",SUMIFS('Bell Schedule'!$C$2:$C$27,'Bell Schedule'!$B$2:$B$27,"Thursday",'Bell Schedule'!$D$2:$D$27,$A5)) | J5: =IF(COUNTIFS('Bell Schedule'!$B$2:$B$27,"Friday",'Bell Schedule'!$D$2:$D$27,$A5)=0,"",SUMIFS('Bell Schedule'!$C$2:$C$27,'Bell Schedule'!$B$2:$B$27,"Friday",'Bell Schedule'!$D$2:$D$27,$A5)) -> 4
A6: E | B6: =COUNTIF('Bell Schedule'!$D$2:$D$27,$A6) -> 3 | C6: =SUMIF('Bell Schedule'!$D$2:$D$27,$A6,'Bell Schedule'!$H$2:$H$27) -> 240 | D6: =SUMIF('Bell Schedule'!$D$2:$D$27,$A6,'Bell Schedule'!$I$2:$I$27) -> 30 | E6: =C6+D6 -> 270 | F6: =IF(COUNTIFS('Bell Schedule'!$B$2:$B$27,"Monday",'Bell Schedule'!$D$2:$D$27,$A6)=0,"",SUMIFS('Bell Schedule'!$C$2:$C$27,'Bell Schedule'!$B$2:$B$27,"Monday",'Bell Schedule'!$D$2:$D$27,$A6)) -> 5 | G6: =IF(COUNTIFS('Bell Schedule'!$B$2:$B$27,"Tuesday",'Bell Schedule'!$D$2:$D$27,$A6)=0,"",SUMIFS('Bell Schedule'!$C$2:$C$27,'Bell Schedule'!$B$2:$B$27,"Tuesday",'Bell Schedule'!$D$2:$D$27,$A6)) | H6: =IF(COUNTIFS('Bell Schedule'!$B$2:$B$27,"Wednesday",'Bell Schedule'!$D$2:$D$27,$A6)=0,"",SUMIFS('Bell Schedule'!$C$2:$C$27,'Bell Schedule'!$B$2:$B$27,"Wednesday",'Bell Schedule'!$D$2:$D$27,$A6)) -> 5 | I6: =IF(COUNTIFS('Bell Schedule'!$B$2:$B$27,"Thursday",'Bell Schedule'!$D$2:$D$27,$A6)=0,"",SUMIFS('Bell Schedule'!$C$2:$C$27,'Bell Schedule'!$B$2:$B$27,"Thursday",'Bell Schedule'!$D$2:$D$27,$A6)) | J6: =IF(COUNTIFS('Bell Schedule'!$B$2:$B$27,"Friday",'Bell Schedule'!$D$2:$D$27,$A6)=0,"",SUMIFS('Bell Schedule'!$C$2:$C$27,'Bell Schedule'!$B$2:$B$27,"Friday",'Bell Schedule'!$D$2:$D$27,$A6)) -> 5
A7: F | B7: =COUNTIF('Bell Schedule'!$D$2:$D$27,$A7) -> 4 | C7: =SUMIF('Bell Schedule'!$D$2:$D$27,$A7,'Bell Schedule'!$H$2:$H$27) -> 240 | D7: =SUMIF('Bell Schedule'!$D$2:$D$27,$A7,'Bell Schedule'!$I$2:$I$27) -> 0 | E7: =C7+D7 -> 240 | F7: =IF(COUNTIFS('Bell Schedule'!$B$2:$B$27,"Monday",'Bell Schedule'!$D$2:$D$27,$A7)=0,"",SUMIFS('Bell Schedule'!$C$2:$C$27,'Bell Schedule'!$B$2:$B$27,"Monday",'Bell Schedule'!$D$2:$D$27,$A7)) | G7: =IF(COUNTIFS('Bell Schedule'!$B$2:$B$27,"Tuesday",'Bell Schedule'!$D$2:$D$27,$A7)=0,"",SUMIFS('Bell Schedule'!$C$2:$C$27,'Bell Schedule'!$B$2:$B$27,"Tuesday",'Bell Schedule'!$D$2:$D$27,$A7)) -> 1 | H7: =IF(COUNTIFS('Bell Schedule'!$B$2:$B$27,"Wednesday",'Bell Schedule'!$D$2:$D$27,$A7)=0,"",SUMIFS('Bell Schedule'!$C$2:$C$27,'Bell Schedule'!$B$2:$B$27,"Wednesday",'Bell Schedule'!$D$2:$D$27,$A7)) -> 2 | I7: =IF(COUNTIFS('Bell Schedule'!$B$2:$B$27,"Thursday",'Bell Schedule'!$D$2:$D$27,$A7)=0,"",SUMIFS('Bell Schedule'!$C$2:$C$27,'Bell Schedule'!$B$2:$B$27,"Thursday",'Bell Schedule'!$D$2:$D$27,$A7)) -> 1 | J7: =IF(COUNTIFS('Bell Schedule'!$B$2:$B$27,"Friday",'Bell Schedule'!$D$2:$D$27,$A7)=0,"",SUMIFS('Bell Schedule'!$C$2:$C$27,'Bell Schedule'!$B$2:$B$27,"Friday",'Bell Schedule'!$D$2:$D$27,$A7)) -> 1
A8: G | B8: =COUNTIF('Bell Schedule'!$D$2:$D$27,$A8) -> 4 | C8: =SUMIF('Bell Schedule'!$D$2:$D$27,$A8,'Bell Schedule'!$H$2:$H$27) -> 240 | D8: =SUMIF('Bell Schedule'!$D$2:$D$27,$A8,'Bell Schedule'!$I$2:$I$27) -> 0 | E8: =C8+D8 -> 240 | F8: =IF(COUNTIFS('Bell Schedule'!$B$2:$B$27,"Monday",'Bell Schedule'!$D$2:$D$27,$A8)=0,"",SUMIFS('Bell Schedule'!$C$2:$C$27,'Bell Schedule'!$B$2:$B$27,"Monday",'Bell Schedule'!$D$2:$D$27,$A8)) | G8: =IF(COUNTIFS('Bell Schedule'!$B$2:$B$27,"Tuesday",'Bell Schedule'!$D$2:$D$27,$A8)=0,"",SUMIFS('Bell Schedule'!$C$2:$C$27,'Bell Schedule'!$B$2:$B$27,"Tuesday",'Bell Schedule'!$D$2:$D$27,$A8)) -> 5 | H8: =IF(COUNTIFS('Bell Schedule'!$B$2:$B$27,"Wednesday",'Bell Schedule'!$D$2:$D$27,$A8)=0,"",SUMIFS('Bell Schedule'!$C$2:$C$27,'Bell Schedule'!$B$2:$B$27,"Wednesday",'Bell Schedule'!$D$2:$D$27,$A8)) -> 4 | I8: =IF(COUNTIFS('Bell Schedule'!$B$2:$B$27,"Thursday",'Bell Schedule'!$D$2:$D$27,$A8)=0,"",SUMIFS('Bell Schedule'!$C$2:$C$27,'Bell Schedule'!$B$2:$B$27,"Thursday",'Bell Schedule'!$D$2:$D$27,$A8)) -> 5 | J8: =IF(COUNTIFS('Bell Schedule'!$B$2:$B$27,"Friday",'Bell Schedule'!$D$2:$D$27,$A8)=0,"",SUMIFS('Bell Schedule'!$C$2:$C$27,'Bell Schedule'!$B$2:$B$27,"Friday",'Bell Schedule'!$D$2:$D$27,$A8)) -> 3
A9: X | B9: =COUNTIF('Bell Schedule'!$D$2:$D$27,$A9) -> 1 | C9: =SUMIF('Bell Schedule'!$D$2:$D$27,$A9,'Bell Schedule'!$H$2:$H$27) -> 45 | D9: =SUMIF('Bell Schedule'!$D$2:$D$27,$A9,'Bell Schedule'!$I$2:$I$27) -> 0 | E9: =C9+D9 -> 45 | F9: =IF(COUNTIFS('Bell Schedule'!$B$2:$B$27,"Monday",'Bell Schedule'!$D$2:$D$27,$A9)=0,"",SUMIFS('Bell Schedule'!$C$2:$C$27,'Bell Schedule'!$B$2:$B$27,"Monday",'Bell Schedule'!$D$2:$D$27,$A9)) | G9: =IF(COUNTIFS('Bell Schedule'!$B$2:$B$27,"Tuesday",'Bell Schedule'!$D$2:$D$27,$A9)=0,"",SUMIFS('Bell Schedule'!$C$2:$C$27,'Bell Schedule'!$B$2:$B$27,"Tuesday",'Bell Schedule'!$D$2:$D$27,$A9)) | H9: =IF(COUNTIFS('Bell Schedule'!$B$2:$B$27,"Wednesday",'Bell Schedule'!$D$2:$D$27,$A9)=0,"",SUMIFS('Bell Schedule'!$C$2:$C$27,'Bell Schedule'!$B$2:$B$27,"Wednesday",'Bell Schedule'!$D$2:$D$27,$A9)) -> 3 | I9: =IF(COUNTIFS('Bell Schedule'!$B$2:$B$27,"Thursday",'Bell Schedule'!$D$2:$D$27,$A9)=0,"",SUMIFS('Bell Schedule'!$C$2:$C$27,'Bell Schedule'!$B$2:$B$27,"Thursday",'Bell Schedule'!$D$2:$D$27,$A9)) | J9: =IF(COUNTIFS('Bell Schedule'!$B$2:$B$27,"Friday",'Bell Schedule'!$D$2:$D$27,$A9)=0,"",SUMIFS('Bell Schedule'!$C$2:$C$27,'Bell Schedule'!$B$2:$B$27,"Friday",'Bell Schedule'!$D$2:$D$27,$A9))
A10: Total | B10: =SUM(B2:B9) -> 26 | C10: =SUM(C2:C9) -> 1725 | D10: =SUM(D2:D9) -> 150 | E10: =SUM(E2:E9) -> 1875
A12: Mon-Fri columns show which period the block meets that day (blank = it doesn't meet).
A13: Cross-check: every lettered block lands on 240 instructional minutes a week. Two independent transcriptions of the scan produced the same result.

Sheet Calendar Events
A1: Date | B1: Weekday | C1: Event Type | D1: Student Status | E1: Likely Holiday (inferred - NOT in the PDF) | F1: Source Colour
A2: 46266 | B2: =TEXT(A2,"dddd") -> Tuesday | C2: Teacher In-Service Day | D2: No school for students | F2: Gray
A3: 46267 | B3: =TEXT(A3,"dddd") -> Wednesday | C3: First Day of School | D3: School in session | F3: Green
A4: 46269 | B4: =TEXT(A4,"dddd") -> Friday | C4: School Closed / Holiday | D4: School closed | F4: Red
A5: 46272 | B5: =TEXT(A5,"dddd") -> Monday | C5: School Closed / Holiday | D5: School closed | E5: Labor Day | F5: Red
A6: 46273 | B6: =TEXT(A6,"dddd") -> Tuesday | C6: First Day - Pre-K & Kindergarten | D6: School in session | F6: Orange
A7: 46295 | B7: =TEXT(A7,"dddd") -> Wednesday | C7: Early Release | D7: Early release | F7: Yellow
A8: 46307 | B8: =TEXT(A8,"dddd") -> Monday | C8: School Closed / Holiday | D8: School closed | E8: Columbus Day / Indigenous Peoples' Day | F8: Red
A9: 46316 | B9: =TEXT(A9,"dddd") -> Wednesday | C9: Early Release | D9: Early release | F9: Yellow
A10: 46329 | B10: =TEXT(A10,"dddd") -> Tuesday | C10: Teacher In-Service Day | D10: No school for students | E10: Election Day | F10: Gray
A11: 46337 | B11: =TEXT(A11,"dddd") -> Wednesday | C11: School Closed / Holiday | D11: School closed | E11: Veterans Day | F11: Red
A12: 46344 | B12: =TEXT(A12,"dddd") -> Wednesday | C12: Early Release | D12: Early release | F12: Yellow
A13: 46351 | B13: =TEXT(A13,"dddd") -> Wednesday | C13: Early Release / Half-Day Holiday | D13: Early release | E13: Day before Thanksgiving | F13: Yellow
A14: 46352 | B14: =TEXT(A14,"dddd") -> Thursday | C14: School Closed / Holiday | D14: School closed | E14: Thanksgiving Day | F14: Red
A15: 46353 | B15: =TEXT(A15,"dddd") -> Friday | C15: School Closed / Holiday | D15: School closed | E15: Day after Thanksgiving | F15: Red
A16: 46365 | B16: =TEXT(A16,"dddd") -> Wednesday | C16: Early Release | D16: Early release | F16: Yellow
A17: 46379 | B17: =TEXT(A17,"dddd") -> Wednesday | C17: Early Release / Half-Day Holiday | D17: Early release | E17: Day before winter recess | F17: Yellow
A18: 46380 | B18: =TEXT(A18,"dddd") -> Thursday | C18: School Closed / Holiday | D18: School closed | E18: Christmas Eve | F18: Red
A19: 46381 | B19: =TEXT(A19,"dddd") -> Friday | C19: School Closed / Holiday | D19: School closed | E19: Christmas Day | F19: Red
A20: 46384 | B20: =TEXT(A20,"dddd") -> Monday | C20: School Closed / Holiday | D20: School closed | E20: Winter recess | F20: Red
A21: 46385 | B21: =TEXT(A21,"dddd") -> Tuesday | C21: School Closed / Holiday | D21: School closed | E21: Winter recess | F21: Red
A22: 46386 | B22: =TEXT(A22,"dddd") -> Wednesday | C22: School Closed / Holiday | D22: School closed | E22: Winter recess | F22: Red
A23: 46387 | B23: =TEXT(A23,"dddd") -> Thursday | C23: School Closed / Holiday | D23: School closed | E23: Winter recess | F23: Red
A24: 46388 | B24: =TEXT(A24,"dddd") -> Friday | C24: School Closed / Holiday | D24: School closed | E24: New Year's Day | F24: Red
A25: 46400 | B25: =TEXT(A25,"dddd") -> Wednesday | C25: Early Release | D25: Early release | F25: Yellow
A26: 46405 | B26: =TEXT(A26,"dddd") -> Monday | C26: School Closed / Holiday | D26: School closed | E26: Martin Luther King Jr. Day | F26: Red
A27: 46428 | B27: =TEXT(A27,"dddd") -> Wednesday | C27: Early Release | D27: Early release | F27: Yellow
A28: 46433 | B28: =TEXT(A28,"dddd") -> Monday | C28: School Closed / Holiday | D28: School closed | E28: Presidents' Day / February vacation | F28: Red
A29: 46434 | B29: =TEXT(A29,"dddd") -> Tuesday | C29: School Closed / Holiday | D29: School closed | E29: February vacation | F29: Red
A30: 46435 | B30: =TEXT(A30,"dddd") -> Wednesday | C30: School Closed / Holiday | D30: School closed | E30: February vacation | F30: Red
A31: 46436 | B31: =TEXT(A31,"dddd") -> Thursday | C31: School Closed / Holiday | D31: School closed | E31: February vacation | F31: Red
A32: 46437 | B32: =TEXT(A32,"dddd") -> Friday | C32: School Closed / Holiday | D32: School closed | E32: February vacation | F32: Red
A33: 46449 | B33: =TEXT(A33,"dddd") -> Wednesday | C33: Early Release | D33: Early release | F33: Yellow
A34: 46463 | B34: =TEXT(A34,"dddd") -> Wednesday | C34: Early Release | D34: Early release | F34: Yellow
A35: 46472 | B35: =TEXT(A35,"dddd") -> Friday | C35: School Closed / Holiday | D35: School closed | E35: Good Friday | F35: Red
A36: 46491 | B36: =TEXT(A36,"dddd") -> Wednesday | C36: Early Release | D36: Early release | F36: Yellow
A37: 46496 | B37: =TEXT(A37,"dddd") -> Monday | C37: School Closed / Holiday | D37: School closed | E37: Patriots' Day / April vacation | F37: Red
A38: 46497 | B38: =TEXT(A38,"dddd") -> Tuesday | C38: School Closed / Holiday | D38: School closed | E38: April vacation | F38: Red
A39: 46498 | B39: =TEXT(A39,"dddd") -> Wednesday | C39: School Closed / Holiday | D39: School closed | E39: April vacation | F39: Red
A40: 46499 | B40: =TEXT(A40,"dddd") -> Thursday | C40: School Closed / Holiday | D40: School closed | E40: April vacation | F40: Red
...

Sheet Monthly Counts
A1: Month | B1: Scheduled School Days | C1: June with 5 Snow Days | D1: Cumulative Scheduled Days | E1: Source Note
A2: 46266 | B2: 19 | D2: =SUM($B$2:B2) -> 19 | E2: September heading: (19)
A3: 46296 | B3: 21 | D3: =SUM($B$2:B3) -> 40 | E3: October heading: (21)
A4: 46327 | B4: 17 | D4: =SUM($B$2:B4) -> 57 | E4: November heading: (17)
A5: 46357 | B5: 17 | D5: =SUM($B$2:B5) -> 74 | E5: December heading: (17)
A6: 46388 | B6: 19 | D6: =SUM($B$2:B6) -> 93 | E6: January heading: (19)
A7: 46419 | B7: 15 | D7: =SUM($B$2:B7) -> 108 | E7: February heading: (15)
A8: 46447 | B8: 22 | D8: =SUM($B$2:B8) -> 130 | E8: March heading: (22)
A9: 46478 | B9: 17 | D9: =SUM($B$2:B9) -> 147 | E9: April heading: (17)
A10: 46508 | B10: 20 | D10: =SUM($B$2:B10) -> 167 | E10: May heading: (20)
A11: 46539 | B11: 13 | C11: 18 | D11: =SUM($B$2:B11) -> 180 | E11: June heading: (13) (18) - 13 scheduled, 18 if all 5 snow days are used
A12: Total | B12: =SUM(B2:B11) -> 180 | D12: =SUM($B$2:$B$10)+C11 -> 185 | E12: Column D total = maximum year length if all 5 snow days are used
A14: Source: weekschedule.pdf p.2, the count printed in each month heading.

Sheet Academic Deadlines
A1: School Level | B1: Term | C1: Term Days | D1: Milestone | E1: Date | F1: Weekday | G1: IPR Day Count
A2: Elementary | B2: T1 | C2: 60 | D2: Trimester IPRs Distribution Date | E2: 46311 | F2: =TEXT(E2,"dddd") -> Friday | G2: 30
A3: Elementary | B3: T1 | C3: 60 | D3: Trimester Closing Date | E3: 46359 | F3: =TEXT(E3,"dddd") -> Thursday
A4: Elementary | B4: T1 | C4: 60 | D4: Trimester Report Card Distribution Date | E4: 46373 | F4: =TEXT(E4,"dddd") -> Thursday
A5: Elementary | B5: T2 | C5: 59 | D5: Trimester IPRs Distribution Date | E5: 46414 | F5: =TEXT(E5,"dddd") -> Wednesday | G5: 31
A6: Elementary | B6: T2 | C6: 59 | D6: Trimester Closing Date | E6: 46458 | F6: =TEXT(E6,"dddd") -> Friday
A7: Elementary | B7: T2 | C7: 59 | D7: Trimester Report Card Distribution Date | E7: 46475 | F7: =TEXT(E7,"dddd") -> Monday
A8: Elementary | B8: T3 | C8: 61 | D8: Trimester IPRs Distribution Date | E8: 46510 | F8: =TEXT(E8,"dddd") -> Monday | G8: 30
A9: Elementary | B9: T3 | C9: 61 | D9: Trimester Closing Date | E9: 46555 | F9: =TEXT(E9,"dddd") -> Thursday
A10: Elementary | B10: T3 | C10: 61 | D10: Trimester Report Card Distribution Date | E10: 46555 | F10: =TEXT(E10,"dddd") -> Thursday
A11: Secondary | B11: Q1 | C11: 44 | D11: Quarter Interim Progress Report | E11: 46297 | F11: =TEXT(E11,"dddd") -> Friday
A12: Secondary | B12: Q1 | C12: 44 | D12: Quarter IPRs Distribution Date | E12: 46304 | F12: =TEXT(E12,"dddd") -> Friday
A13: Secondary | B13: Q1 | C13: 44 | D13: Quarter Closing Date | E13: 46332 | F13: =TEXT(E13,"dddd") -> Friday
A14: Secondary | B14: Q1 | C14: 44 | D14: Quarter Report Card Distribution Date | E14: 46342 | F14: =TEXT(E14,"dddd") -> Monday
A15: Secondary | B15: Q2 | C15: 44 | D15: Quarter Interim Progress Report | E15: 46367 | F15: =TEXT(E15,"dddd") -> Friday
A16: Secondary | B16: Q2 | C16: 44 | D16: Quarter IPRs Distribution Date | E16: 46374 | F16: =TEXT(E16,"dddd") -> Friday
A17: Secondary | B17: Q2 | C17: 44 | D17: Quarter Closing Date | E17: 46409 | F17: =TEXT(E17,"dddd") -> Friday
A18: Secondary | B18: Q2 | C18: 44 | D18: Quarter Report Card Distribution Date | E18: 46416 | F18: =TEXT(E18,"dddd") -> Friday
A19: Secondary | B19: Q3 | C19: 52 | D19: Quarter Interim Progress Report | E19: 46451 | F19: =TEXT(E19,"dddd") -> Friday
A20: Secondary | B20: Q3 | C20: 52 | D20: Quarter IPRs Distribution Date | E20: 46458 | F20: =TEXT(E20,"dddd") -> Friday
... A26: Secondary | B26: Q4 | C26: 40 | D26: Quarter Report Card Distribution Date | E26: 46555 | F26: =TEXT(E26,"dddd") -> Thursday
A28: Source: weekschedule.pdf p.2, the two tables at the foot of the calendar page.
